<?xml version="1.0" encoding="utf-8"?>
<robot name="mintchoco1" xmlns:xacro="http://ros.org/wiki/xacro">

  <!-- Fix the base_link -->
  <link name="world"/>

  <joint name="fixed" type="fixed">
    <parent link="world"/>
    <child link="base_link"/>
     <origin xyz="0.0 0.0 0.005" rpy="0 0 0" />
  </joint>

  <link name="base_link">
    <inertial>
      <origin
        xyz="0.00035091 -1.3484E-17 -0.0043115"
        rpy="0 0 0" />
      <mass
        value="0.66707" />
      <inertia
        ixx="0.00059432"
        ixy="-1.0895E-18"
        ixz="3.1949E-21"
        iyy="0.00060798"
        iyz="-1.7633E-08"
        izz="0.00093172" />
    </inertial>
    <visual>
      <origin
        xyz="0 0 0"
        rpy="0 0 0" />
      <geometry>
        <mesh
          filename="package://mintchoco1_description/meshes/base_link.STL" />
      </geometry>
      <material
        name="">
        <color
          rgba="0.79216 0.81961 0.93333 1" />
      </material>
    </visual>
    <collision>
      <origin
        xyz="0 0 0"
        rpy="0 0 0" />
      <geometry>
        <mesh
          filename="package://mintchoco1_description/meshes/base_link.STL" />
      </geometry>
    </collision>
  </link>
  <link
    name="LF_link1">
    <inertial>
      <origin
        xyz="-0.024455 0.035154 0.00033392"
        rpy="0 0 0" />
      <mass
        value="0.081435" />
      <inertia
        ixx="2.7163E-05"
        ixy="1.2278E-06"
        ixz="-1.4412E-08"
        iyy="2.8585E-05"
        iyz="-2.5385E-07"
        izz="1.9479E-05" />
    </inertial>
    <visual>
      <origin
        xyz="0 0 0"
        rpy="0 0 0" />
      <geometry>
        <mesh
          filename="package://mintchoco1_description/meshes/LF_link1.STL" />
      </geometry>
      <material
        name="">
        <color
          rgba="0.79216 0.81961 0.93333 1" />
      </material>
    </visual>
    <collision>
      <origin
        xyz="0 0 0"
        rpy="0 0 0" />
      <geometry>
        <mesh
          filename="package://mintchoco1_description/meshes/LF_link1.STL" />
      </geometry>
    </collision>
  </link>
  <joint
    name="LF_joint1"
    type="revolute">
    <origin
      xyz="0.1515 0.04025 -0.00175"
      rpy="0 0 0" />
    <parent
      link="base_link" />
    <child
      link="LF_link1" />
    <axis
      xyz="-0.99995 0 0.010204" />
    <limit
      lower="-3.14"
      upper="3.14"
      effort="0"
      velocity="0" />
  </joint>
  <link
    name="LF_link2">
    <inertial>
      <origin
        xyz="0.00096259 -0.097555 -0.0025994"
        rpy="0 0 0" />
      <mass
        value="0.25649" />
      <inertia
        ixx="0.00086048"
        ixy="-1.0049E-06"
        ixz="-2.5703E-07"
        iyy="5.3981E-05"
        iyz="1.0286E-05"
        izz="0.00085527" />
    </inertial>
    <visual>
      <origin
        xyz="0 0 0"
        rpy="0 0 0" />
      <geometry>
        <mesh
          filename="package://mintchoco1_description/meshes/LF_link2.STL" />
      </geometry>
      <material
        name="">
        <color
          rgba="0.79216 0.81961 0.93333 1" />
      </material>
    </visual>
    <collision>
      <origin
        xyz="0 0 0"
        rpy="0 0 0" />
      <geometry>
        <mesh
          filename="package://mintchoco1_description/meshes/LF_link2.STL" />
      </geometry>
    </collision>
  </link>
  <joint
    name="LF_joint2"
    type="revolute">
    <origin
      xyz="-0.024 0.079 0.0125"
      rpy="0 0 -1.5708" />
    <parent
      link="LF_link1" />
    <child
      link="LF_link2" />
    <axis
      xyz="1 0 0" />
    <limit
      lower="-3.14"
      upper="3.14"
      effort="0"
      velocity="0" />
  </joint>
  <link
    name="LF_link3">
    <inertial>
      <origin
        xyz="0.021928 4.0475E-05 -0.1015"
        rpy="0 0 0" />
      <mass
        value="0.080926" />
      <inertia
        ixx="0.00020706"
        ixy="-2.2414E-09"
        ixz="4.9749E-06"
        iyy="0.00020883"
        iyz="1.0221E-08"
        izz="7.6685E-06" />
    </inertial>
    <visual>
      <origin
        xyz="0 0 0"
        rpy="0 0 0" />
      <geometry>
        <mesh
          filename="package://mintchoco1_description/meshes/LF_link3.STL" />
      </geometry>
      <material
        name="">
        <color
          rgba="0.79216 0.81961 0.93333 1" />
      </material>
    </visual>
    <collision>
      <origin
        xyz="0 0 0"
        rpy="0 0 0" />
      <geometry>
        <mesh
          filename="package://mintchoco1_description/meshes/LF_link3.STL" />
      </geometry>
    </collision>
  </link>
  <joint
    name="LF_joint3"
    type="revolute">
    <origin
      xyz="-0.022 -0.18525 -0.03025"
      rpy="0 0 0" />
    <parent
      link="LF_link2" />
    <child
      link="LF_link3" />
    <axis
      xyz="-1 -0.0017021 0" />
    <limit
      lower="-3.14"
      upper="3.14"
      effort="0"
      velocity="0" />
  </joint>
  <link
    name="RF_link1">
    <inertial>
      <origin
        xyz="-0.024443 -0.035154 0.00032454"
        rpy="0 0 0" />
      <mass
        value="0.081435" />
      <inertia
        ixx="2.7163E-05"
        ixy="-1.2382E-06"
        ixz="1.4412E-08"
        iyy="2.8585E-05"
        iyz="2.5703E-07"
        izz="1.9479E-05" />
    </inertial>
    <visual>
      <origin
        xyz="0 0 0"
        rpy="0 0 0" />
      <geometry>
        <mesh
          filename="package://mintchoco1_description/meshes/RF_link1.STL" />
      </geometry>
      <material
        name="">
        <color
          rgba="0.79216 0.81961 0.93333 1" />
      </material>
    </visual>
    <collision>
      <origin
        xyz="0 0 0"
        rpy="0 0 0" />
      <geometry>
        <mesh
          filename="package://mintchoco1_description/meshes/RF_link1.STL" />
      </geometry>
    </collision>
  </link>
  <joint
    name="RF_joint1"
    type="revolute">
    <origin
      xyz="0.1515 -0.04025 -0.00175"
      rpy="0 0 0" />
    <parent
      link="base_link" />
    <child
      link="RF_link1" />
    <axis
      xyz="-0.99999 0 0.005102" />
    <limit
      lower="-3.14"
      upper="3.14"
      effort="0"
      velocity="0" />
  </joint>
  <link
    name="RF_link2">
    <inertial>
      <origin
        xyz="-0.00096259 -0.097559 -0.0025994"
        rpy="0 0 0" />
      <mass
        value="0.25649" />
      <inertia
        ixx="0.00086048"
        ixy="9.9438E-07"
        ixz="2.5703E-07"
        iyy="5.3981E-05"
        iyz="1.0295E-05"
        izz="0.00085527" />
    </inertial>
    <visual>
      <origin
        xyz="0 0 0"
        rpy="0 0 0" />
      <geometry>
        <mesh
          filename="package://mintchoco1_description/meshes/RF_link2.STL" />
      </geometry>
      <material
        name="">
        <color
          rgba="0.79216 0.81961 0.93333 1" />
      </material>
    </visual>
    <collision>
      <origin
        xyz="0 0 0"
        rpy="0 0 0" />
      <geometry>
        <mesh
          filename="package://mintchoco1_description/meshes/RF_link2.STL" />
      </geometry>
    </collision>
  </link>
  <joint
    name="RF_joint2"
    type="revolute">
    <origin
      xyz="-0.024 -0.079 0.0125"
      rpy="0 0 -1.5708" />
    <parent
      link="RF_link1" />
    <child
      link="RF_link2" />
    <axis
      xyz="-1 0 0" />
    <limit
      lower="-3.14"
      upper="3.14"
      effort="0"
      velocity="0" />
  </joint>
  <link
    name="RF_link3">
    <inertial>
      <origin
        xyz="-0.021928 -4.0475E-05 -0.1015"
        rpy="0 0 0" />
      <mass
        value="0.080926" />
      <inertia
        ixx="0.00020706"
        ixy="-2.2414E-09"
        ixz="-4.9749E-06"
        iyy="0.00020883"
        iyz="-1.0221E-08"
        izz="7.6685E-06" />
    </inertial>
    <visual>
      <origin
        xyz="0 0 0"
        rpy="0 0 0" />
      <geometry>
        <mesh
          filename="package://mintchoco1_description/meshes/RF_link3.STL" />
      </geometry>
      <material
        name="">
        <color
          rgba="0.79216 0.81961 0.93333 1" />
      </material>
    </visual>
    <collision>
      <origin
        xyz="0 0 0"
        rpy="0 0 0" />
      <geometry>
        <mesh
          filename="package://mintchoco1_description/meshes/RF_link3.STL" />
      </geometry>
    </collision>
  </link>
  <joint
    name="RF_joint3"
    type="revolute">
    <origin
      xyz="0.022 -0.18525 -0.03025"
      rpy="0 0 0" />
    <parent
      link="RF_link2" />
    <child
      link="RF_link3" />
    <axis
      xyz="-1 -0.0017021 0" />
    <limit
      lower="-3.14"
      upper="3.14"
      effort="0"
      velocity="0" />
  </joint>
  <link
    name="LB_link1">
    <inertial>
      <origin
        xyz="-0.024455 0.035154 0.00033392"
        rpy="0 0 0" />
      <mass
        value="0.081435" />
      <inertia
        ixx="2.7163E-05"
        ixy="1.2278E-06"
        ixz="-1.4412E-08"
        iyy="2.8585E-05"
        iyz="-2.5385E-07"
        izz="1.9479E-05" />
    </inertial>
    <visual>
      <origin
        xyz="0 0 0"
        rpy="0 0 0" />
      <geometry>
        <mesh
          filename="package://mintchoco1_description/meshes/LB_link1.STL" />
      </geometry>
      <material
        name="">
        <color
          rgba="0.79216 0.81961 0.93333 1" />
      </material>
    </visual>
    <collision>
      <origin
        xyz="0 0 0"
        rpy="0 0 0" />
      <geometry>
        <mesh
          filename="package://mintchoco1_description/meshes/LB_link1.STL" />
      </geometry>
    </collision>
  </link>
  <joint
    name="LB_joint1"
    type="revolute">
    <origin
      xyz="-0.1025 0.04025 -0.00175"
      rpy="0 0 0" />
    <parent
      link="base_link" />
    <child
      link="LB_link1" />
    <axis
      xyz="0.99995 0 -0.010204" />
    <limit
      lower="-3.14"
      upper="3.14"
      effort="0"
      velocity="0" />
  </joint>
  <link
    name="LB_link2">
    <inertial>
      <origin
        xyz="0.00096259 -0.097555 -0.0025994"
        rpy="0 0 0" />
      <mass
        value="0.25649" />
      <inertia
        ixx="0.00086048"
        ixy="-1.0049E-06"
        ixz="-2.5703E-07"
        iyy="5.3981E-05"
        iyz="1.0286E-05"
        izz="0.00085527" />
    </inertial>
    <visual>
      <origin
        xyz="0 0 0"
        rpy="0 0 0" />
      <geometry>
        <mesh
          filename="package://mintchoco1_description/meshes/LB_link2.STL" />
      </geometry>
      <material
        name="">
        <color
          rgba="0.79216 0.81961 0.93333 1" />
      </material>
    </visual>
    <collision>
      <origin
        xyz="0 0 0"
        rpy="0 0 0" />
      <geometry>
        <mesh
          filename="package://mintchoco1_description/meshes/LB_link2.STL" />
      </geometry>
    </collision>
  </link>
  <joint
    name="LB_joint2"
    type="revolute">
    <origin
      xyz="-0.024 0.079 0.0125"
      rpy="0 0 -1.5708" />
    <parent
      link="LB_link1" />
    <child
      link="LB_link2" />
    <axis
      xyz="1 0 0" />
    <limit
      lower="-3.14"
      upper="3.14"
      effort="0"
      velocity="0" />
  </joint>
  <link
    name="LB_link3">
    <inertial>
      <origin
        xyz="0.021928 3.6546E-05 -0.1015"
        rpy="0 0 0" />
      <mass
        value="0.080926" />
      <inertia
        ixx="0.00020706"
        ixy="-2.2414E-09"
        ixz="4.9749E-06"
        iyy="0.00020883"
        iyz="1.0221E-08"
        izz="7.6685E-06" />
    </inertial>
    <visual>
      <origin
        xyz="0 0 0"
        rpy="0 0 0" />
      <geometry>
        <mesh
          filename="package://mintchoco1_description/meshes/LB_link3.STL" />
      </geometry>
      <material
        name="">
        <color
          rgba="0.79216 0.81961 0.93333 1" />
      </material>
    </visual>
    <collision>
      <origin
        xyz="0 0 0"
        rpy="0 0 0" />
      <geometry>
        <mesh
          filename="package://mintchoco1_description/meshes/LB_link3.STL" />
      </geometry>
    </collision>
  </link>
  <joint
    name="LB_joint3"
    type="revolute">
    <origin
      xyz="-0.022 -0.18525 -0.03025"
      rpy="0 0 0" />
    <parent
      link="LB_link2" />
    <child
      link="LB_link3" />
    <axis
      xyz="-1 0 0" />
    <limit
      lower="-3.14"
      upper="3.14"
      effort="0"
      velocity="0" />
  </joint>
  <link
    name="RB_link1">
    <inertial>
      <origin
        xyz="-0.024443 -0.035154 0.00032454"
        rpy="0 0 0" />
      <mass
        value="0.081435" />
      <inertia
        ixx="2.7163E-05"
        ixy="-1.2382E-06"
        ixz="1.4412E-08"
        iyy="2.8585E-05"
        iyz="2.5703E-07"
        izz="1.9479E-05" />
    </inertial>
    <visual>
      <origin
        xyz="0 0 0"
        rpy="0 0 0" />
      <geometry>
        <mesh
          filename="package://mintchoco1_description/meshes/RB_link1.STL" />
      </geometry>
      <material
        name="">
        <color
          rgba="0.79216 0.81961 0.93333 1" />
      </material>
    </visual>
    <collision>
      <origin
        xyz="0 0 0"
        rpy="0 0 0" />
      <geometry>
        <mesh
          filename="package://mintchoco1_description/meshes/RB_link1.STL" />
      </geometry>
    </collision>
  </link>
  <joint
    name="RB_joint1"
    type="revolute">
    <origin
      xyz="-0.1025 -0.04025 -0.00175"
      rpy="0 0 0" />
    <parent
      link="base_link" />
    <child
      link="RB_link1" />
    <axis
      xyz="0.99999 0 -0.005102" />
    <limit
      lower="-3.14"
      upper="3.14"
      effort="0"
      velocity="0" />
  </joint>
  <link
    name="RB_link2">
    <inertial>
      <origin
        xyz="-0.00096259 -0.097559 -0.0025994"
        rpy="0 0 0" />
      <mass
        value="0.25649" />
      <inertia
        ixx="0.00086048"
        ixy="9.9438E-07"
        ixz="2.5703E-07"
        iyy="5.3981E-05"
        iyz="1.0295E-05"
        izz="0.00085527" />
    </inertial>
    <visual>
      <origin
        xyz="0 0 0"
        rpy="0 0 0" />
      <geometry>
        <mesh
          filename="package://mintchoco1_description/meshes/RB_link2.STL" />
      </geometry>
      <material
        name="">
        <color
          rgba="0.79216 0.81961 0.93333 1" />
      </material>
    </visual>
    <collision>
      <origin
        xyz="0 0 0"
        rpy="0 0 0" />
      <geometry>
        <mesh
          filename="package://mintchoco1_description/meshes/RB_link2.STL" />
      </geometry>
    </collision>
  </link>
  <joint
    name="RB_joint2"
    type="revolute">
    <origin
      xyz="-0.024 -0.079 0.0125"
      rpy="0 0 -1.5708" />
    <parent
      link="RB_link1" />
    <child
      link="RB_link2" />
    <axis
      xyz="-1 0 0" />
    <limit
      lower="-3.14"
      upper="3.14"
      effort="0"
      velocity="0" />
  </joint>
  <link
    name="RB_link3">
    <inertial>
      <origin
        xyz="-0.021928 -4.0475E-05 -0.1015"
        rpy="0 0 0" />
      <mass
        value="0.080926" />
      <inertia
        ixx="0.00020706"
        ixy="-2.2414E-09"
        ixz="-4.9749E-06"
        iyy="0.00020883"
        iyz="-1.0221E-08"
        izz="7.6685E-06" />
    </inertial>
    <visual>
      <origin
        xyz="0 0 0"
        rpy="0 0 0" />
      <geometry>
        <mesh
          filename="package://mintchoco1_description/meshes/RB_link3.STL" />
      </geometry>
      <material
        name="">
        <color
          rgba="0.79216 0.81961 0.93333 1" />
      </material>
    </visual>
    <collision>
      <origin
        xyz="0 0 0"
        rpy="0 0 0" />
      <geometry>
        <mesh
          filename="package://mintchoco1_description/meshes/RB_link3.STL" />
      </geometry>
    </collision>
  </link>
  <joint
    name="RB_joint3"
    type="revolute">
    <origin
      xyz="0.022 -0.18525 -0.03025"
      rpy="0 0 0" />
    <parent
      link="RB_link2" />
    <child
      link="RB_link3" />
    <axis
      xyz="1 0.0017021 0" />
    <limit
      lower="-3.14"
      upper="3.14"
      effort="0"
      velocity="0" />
  </joint>
</robot>
